['Traceback (most recent call last):\n', '  File "/home/mfvuser/mfvmis_staging_venv/lib/python3.8/site-packages/django/db/backends/utils.py", line 89, in _execute\n    return self.cursor.execute(sql, params)\n', 'psycopg2.errors.UndefinedTable: relation "send_mail_maildata" does not exist\nLINE 1: ...a"."mode", "send_mail_maildata"."file_paths" FROM "send_mail...\n                                                             ^\n\n', '\nThe above exception was the direct cause of the following exception:\n\n', 'Traceback (most recent call last):\n', '  File "/home/mfvuser/mfvmis_dev/send_mail/management/commands/send_email.py", line 59, in handle\n    sendmail()\n', '  File "/home/mfvuser/mfvmis_dev/send_mail/management/commands/send_email.py", line 16, in sendmail\n    for x in mail_obj:\n', '  File "/home/mfvuser/mfvmis_staging_venv/lib/python3.8/site-packages/django/db/models/query.py", line 398, in __iter__\n    self._fetch_all()\n', '  File "/home/mfvuser/mfvmis_staging_venv/lib/python3.8/site-packages/django/db/models/query.py", line 1881, in _fetch_all\n    self._result_cache = list(self._iterable_class(self))\n', '  File "/home/mfvuser/mfvmis_staging_venv/lib/python3.8/site-packages/django/db/models/query.py", line 91, in __iter__\n    results = compiler.execute_sql(\n', '  File "/home/mfvuser/mfvmis_staging_venv/lib/python3.8/site-packages/django/db/models/sql/compiler.py", line 1562, in execute_sql\n    cursor.execute(sql, params)\n', '  File "/home/mfvuser/mfvmis_staging_venv/lib/python3.8/site-packages/django/db/backends/utils.py", line 67, in execute\n    return self._execute_with_wrappers(\n', '  File "/home/mfvuser/mfvmis_staging_venv/lib/python3.8/site-packages/django/db/backends/utils.py", line 80, in _execute_with_wrappers\n    return executor(sql, params, many, context)\n', '  File "/home/mfvuser/mfvmis_staging_venv/lib/python3.8/site-packages/django/db/backends/utils.py", line 89, in _execute\n    return self.cursor.execute(sql, params)\n', '  File "/home/mfvuser/mfvmis_staging_venv/lib/python3.8/site-packages/django/db/utils.py", line 91, in __exit__\n    raise dj_exc_value.with_traceback(traceback) from exc_value\n', '  File "/home/mfvuser/mfvmis_staging_venv/lib/python3.8/site-packages/django/db/backends/utils.py", line 89, in _execute\n    return self.cursor.execute(sql, params)\n', 'django.db.utils.ProgrammingError: relation "send_mail_maildata" does not exist\nLINE 1: ...a"."mode", "send_mail_maildata"."file_paths" FROM "send_mail...\n                                                             ^\n\n']
